#VRML_SIM R2023b utf8

EXTERNPROTO "https://raw.githubusercontent.com/cyberbotics/webots/R2023b/projects/objects/backgrounds/protos/TexturedBackground.proto"
EXTERNPROTO "https://raw.githubusercontent.com/cyberbotics/webots/R2023b/projects/objects/backgrounds/protos/TexturedBackgroundLight.proto"
EXTERNPROTO "https://raw.githubusercontent.com/cyberbotics/webots/R2023b/projects/objects/robotstadium/protos/RobotstadiumSoccerField.proto"

WorldInfo {
}
Viewpoint {
  fieldOfView 1
  orientation 0.09704641584879595 -0.8969031620262797 -0.43144722865973245 5.791745494840013
  position -3.562138112437036 -0.24752406272156202 1.5912495412232723
}
TexturedBackground {
}
TexturedBackgroundLight {
}
DEF Ball Robot {
  translation 0.04 0 0.05
  children [
    DEF ballSphere Shape {
      appearance Appearance {
        material Material {
          ambientIntensity 0
        }
      }
      geometry Sphere {
        radius 0.05
      }
    }
  ]
  name "ball"
  boundingObject USE ballSphere
  physics Physics {
    mass 1
  }
  controller "soccer-ball"
}
RobotstadiumSoccerField {
}
DEF GoalLine Robot {
  translation 4.77 0 0
  children [
    Shape {
      appearance Appearance {
        material Material {
          diffuseColor 1 0 0
          emissiveColor 1 0 0
          specularColor 1 0 0
        }
      }
      geometry Box {
        size 0.53 1.5 0.001
      }
    }
  ]
  name "goalline"
}
Robot {
  translation 0 -0.2 0.17984
  rotation 1 0 0 -1.57
  children [
    DEF PlayerBody Pose {
      translation -0.96 0 0.17
      children [
        Shape {
          appearance PBRAppearance {
            baseColor 0.9 0.5 0
            roughness 1
            metalness 0
          }
          geometry Box {
            size 0.3 0.3 0.3
          }
        }
      ]
    }
    HingeJoint {
      jointParameters HingeJointParameters {
        position 56.1211339601632
        axis 0 0 1
        anchor -0.96 0.1 0.331
      }
      device [
        RotationalMotor {
          name "motor_1"
        }
      ]
      endPoint Solid {
        translation -0.959963019293156 0.09999494208084966 0.3309999702771004
        children [
          DEF Wheel Shape {
            appearance PBRAppearance {
              baseColor 0 0 1
              roughness 1
              metalness 0
            }
            geometry Cylinder {
              height 0.03
              radius 0.08
            }
          }
        ]
        boundingObject USE Wheel
        physics DEF wheel_physics Physics {
        }
      }
    }
    HingeJoint {
      jointParameters HingeJointParameters {
        axis 0 0 1
        anchor -0.96 0.1 0.01
      }
      device [
        RotationalMotor {
          name "motor_2"
        }
      ]
      endPoint Solid {
        translation -0.96 0.10003736339492576 0.010000112906892159
        rotation 1 0 0 5.487189483500131e-07
        children [
          USE Wheel
        ]
        name "solid(1)"
        boundingObject USE Wheel
        physics USE wheel_physics
      }
    }
    Solid {
      translation -0.8 -0.08 0.09
      children [
        DEF eyes Shape {
          appearance PBRAppearance {
            baseColor 0 0 1
            roughness 1
            metalness 0
          }
          geometry Sphere {
            radius 0.018
          }
        }
      ]
      name "solid(2)"
    }
    Solid {
      translation -0.8 -0.08 0.25
      children [
        USE eyes
      ]
      name "solid(3)"
    }
  ]
  name "Goalie"
  boundingObject USE PlayerBody
  physics Physics {
  }
  controller "goalie"
}
DEF SUPERVISOR Robot {
  controller "supervisor"
  supervisor TRUE
}
