#VRML_SIM R2023b utf8

EXTERNPROTO "https://raw.githubusercontent.com/cyberbotics/webots/R2023b/projects/objects/backgrounds/protos/TexturedBackground.proto"
EXTERNPROTO "https://raw.githubusercontent.com/cyberbotics/webots/R2023b/projects/objects/backgrounds/protos/TexturedBackgroundLight.proto"
EXTERNPROTO "https://raw.githubusercontent.com/cyberbotics/webots/R2023b/projects/objects/robotstadium/protos/RobotstadiumSoccerField.proto"

WorldInfo {
}
Viewpoint {
  fieldOfView 1
  orientation 0.09050099320243613 -0.0004424611058183033 -0.9958962669161596 3.1513304888535387
  position 0.31989253428645015 -0.04304566513446786 0.5384512691100426
}
TexturedBackground {
}
TexturedBackgroundLight {
}
DEF Ball Robot {
  translation 0.04 0 0.05
  children [
    Shape {
      appearance Appearance {
        material Material {
          ambientIntensity 0
        }
      }
      geometry Sphere {
        radius 0.05
      }
    }
  ]
  name "ball"
  controller "soccer-ball"
}
RobotstadiumSoccerField {
}
DEF GoalLine Robot {
  translation 4.77 0 0
  children [
    Shape {
      appearance Appearance {
        material Material {
          diffuseColor 1 0 0
          emissiveColor 1 0 0
          specularColor 1 0 0
        }
      }
      geometry Box {
        size 0.53 1.5 0.001
      }
    }
  ]
  name "goalline"
}
Robot {
  children [
    DEF PlayerBody Pose {
      translation -0.96 0 0.17
      children [
        Shape {
          appearance PBRAppearance {
            baseColor 0.9 0.5 0
            roughness 1
            metalness 0
          }
          geometry Box {
            size 0.3 0.3 0.3
          }
        }
      ]
    }
    HingeJoint {
      jointParameters HingeJointParameters {
        anchor -0.96 0.16 0.08
      }
      device [
        RotationalMotor {
          name "motor_1"
        }
      ]
      endPoint Solid {
        translation -0.96 0.16 0.08
        rotation 1 0 0 1.57
        children [
          DEF Wheel Shape {
            appearance PBRAppearance {
              baseColor 0 0 1
              roughness 1
              metalness 0
            }
            geometry Cylinder {
              height 0.03
              radius 0.08
            }
          }
        ]
        boundingObject USE Wheel
        physics DEF wheel_physics Physics {
        }
      }
    }
    HingeJoint {
      jointParameters HingeJointParameters {
        anchor -0.96 -0.16 0.08
      }
      device [
        RotationalMotor {
          name "motor_2"
        }
      ]
      endPoint Solid {
        translation -0.96 -0.16 0.08
        rotation 1 0 0 1.57
        children [
          USE Wheel
        ]
        name "solid(1)"
        boundingObject USE Wheel
        physics USE wheel_physics
      }
    }
    Solid {
      translation -0.8 0.08 0.25
      children [
        DEF eyes Shape {
          appearance PBRAppearance {
            baseColor 0 0 1
            roughness 1
            metalness 0
          }
          geometry Sphere {
            radius 0.018
          }
        }
      ]
      name "solid(2)"
    }
    Solid {
      translation -0.8 -0.08 0.25
      children [
        USE eyes
      ]
      name "solid(3)"
    }
  ]
  name "Goalie"
  boundingObject USE PlayerBody
  physics Physics {
  }
  controller "<none>"
}
DEF SUPERVISOR Robot {
  controller "supervisor"
  supervisor TRUE
}
